Workbook

Sheet Cronograma
B2: Revisitação Obrigações 2022 / 2023 / 2024
B3: Outubro
B4: Seg | C4: Ter | D4: Qua | E4: Qui | F4: Sex
B5: 13 | C5: 14 | D5: 15 | E5: 16 | F5: 17
B6: Juliana Cabral (1) 14:30 - 15:00 | C6: Fernando Rodrigues (2) 09:00 - 10:00 | D6: Walcy Borges (1) 11:30 - 12:00 | E6: Luciana Santos (13) 11:00 - 12:00 | F6: Leonardo Medina (1) 15:00 - 15:30
B7: Larissa Valois (2) 15:00 - 15:30 | C7: Walcy Borges (1) 14:00 - 14:30 | D7: ** | E7: ** | F7: **
B8: ** | C8: Leonardo Medina (1) 15:00 - 15:30 | D8: ** | E8: ** | F8: **
B9: Seg | C9: Ter | D9: Qua | E9: Qui | F9: Sex
B10: 20 | C10: 21 | D10: 22 | E10: 23 | F10: 24
B11: ** | C11: ** | D11: Luciana Santos (13) 09:00 - 10:00 | E11: ** | F11: **
B14: Revisitação Obrigações 2025
B15: Outubro
B16: Seg | C16: Ter | D16: Qua | E16: Qui | F16: Sex
B17: 6 | C17: 7 | D17: 8 | E17: 9 | F17: 10
B18: Fabio Mota 15:00 - 16:00 | C18: ** | D18: ** | E18: Fabio Mota 14:00 - 15:00 | F18: **
B19: Seg | C19: Ter | D19: Qua | E19: Qui | F19: Sex
B20: 13 | C20: 14 | D20: 15 | E20: 16 | F20: 17
B21: ** | C21: ** | D21: Fabio Mota 13:30 - 15:00 | E21: Fabio Mota 13:30 - 15:00 | F21: **
B22: Seg | C22: Ter | D22: Qua | E22: Qui | F22: Sex
B23: 20 | C23: 21 | D23: 22 | E23: 23 | F23: 24
B24: ** | C24: Fernando Rodrigues 15:00 - 16:00 | D24: ** | E24: Fabio Mota 15:00 - 16:30 | F24: Fernando Rodrigues 14:30 - 15:30
B25: Seg | C25: Ter | D25: Qua | E25: Qui | F25: Sex
B26: 27 | C26: 28 | D26: 29 | E26: 30 | F26: 31
B27: Fernando Rodrigues 14:00 - 15:30 | C27: Luciana Santos 14:00 - 15:00 | D27: Fabio Mota 14:00 - 15:00 | E27: Fabio Mota 14:00 - 15:00 | F27: **
B28: Novembro
B29: Seg | C29: Ter | D29: Qua | E29: Qui | F29: Sex
B30: 3 | C30: 4 | D30: 5 | E30: 6 | F30: 7
B31: Fernando Rodrigues 14:00 - 15:00 | C31: Fabio Mota 09:00 - 10:00 | D31: ** | E31: ** | F31: **
B32: ** | C32: Fernando Rodrigues 14:00 - 15:00 | D32: ** | E32: ** | F32: **
B33: Seg | C33: Ter | D33: Qua | E33: Qui | F33: Sex
B34: 10 | C34: 11 | D34: 12 | E34: 13 | F34: 14
B35: Marcelo Ribeiro 14:00 - 15:00 | C35: Fernando Rodrigues 14:00 - 15:00 | D35: ** | E35: ** | F35: Fabio Mota 14:00 - 15:30
B36: Seg | C36: Ter | D36: Qua | E36: Qui | F36: Sex
B37: 17 | C37: 18 | D37: 19 | E37: 20 | F37: 21
B38: Análise das respostas das obrigações anteriores a 2025 09:00 - 11:30 | C38: ** | D38: Análise Crítica SEG | E38: Feriado | F38: **
B39: Seg | C39: Ter | D39: Qua | E39: Qui | F39: Sex
B40: 24 | C40: 25 | D40: 26 | E40: 27 | F40: 28
B41: Fabio Mota 15:00 - 16:00 | C41: Análise das respostas das obrigações anteriores a 2025 09:00 - 10:30 | D41: Fabio Mota 09:00 - 10:00 | E41: ** | F41: Fabio Mota 14:00 - 15:00
B42: Dezembro
B43: Seg | C43: Ter | D43: Qua | E43: Qui | F43: Sex
...

Sheet Resumo
B2: ATIVO I
B4: Contagem de Situação - ATIVO I | C4: Rótulos de Coluna
B5: Rótulos de Linha | C5: Devolver | D5: Não Respondida | E5: Respondida | F5: Transferir | G5: Abrir RTA | H5: Total Geral
B6: Arnaldo Carvalho - ZMIG | D6: 1 | H6: 1
B7: Bruno Lopes-PL2F | E7: 4 | H7: 4
B8: Em análise | F8: 31 | H8: 31
B9: FABIO MOTA DXV9 | C9: 21 | D9: 1 | E9: 134 | H9: 156
B10: Felipe Sampaio- ZP4I | D10: 9 | E10: 24 | F10: 1 | G10: 3 | H10: 37
B11: Fernando Rodrigues- CMQ6 | C11: 1 | D11: 4 | E11: 76 | F11: 44 | H11: 125
B12: Francisco Batalha- URFV | E12: 8 | H12: 8
B13: Juliana Cabral-CYT6 | D13: 3 | E13: 10 | F13: 1 | H13: 14
B14: Larissa Valois-FIUX | D14: 2 | E14: 31 | F14: 10 | H14: 43
B15: LEONARDO MEDINA - CSQE | E15: 40 | H15: 40
B16: Luciana Santos-URFU | D16: 1 | E16: 24 | H16: 25
B17: Marcelo Ribeiro - URWD | E17: 6 | H17: 6
B18: Walcy Borges- SESM | D18: 38 | E18: 22 | F18: 3 | H18: 63
B19: Walter Motta- F49B | E19: 7 | H19: 7
B20: Alex Angeli - FLVR | D20: 52 | H20: 52
B21: Juliana Cabral-CYT6 Luciano Dumiense-F5WZ | E21: 1 | H21: 1
B22: Total Geral | C22: 22 | D22: 111 | E22: 387 | F22: 90 | G22: 3 | H22: 613

Sheet Resumo 2 - RAC
B2: ATIVO I
B4: Contagem de Situação - ATIVO I | C4: Rótulos de Coluna
B5: Rótulos de Linha | C5: Não Respondida | D5: Respondida | E5: Total Geral
B6: Abrangência | C6: 1 | E6: 1
B7: Gerir Anomalias de SMS | C7: 3 | D7: 11 | E7: 14
B8: Gerir Ergonomia | C8: 9 | D8: 24 | E8: 33
B9: Gerir Higiene Ocupacional | D9: 49 | E9: 49
B10: Gerir M&I de Equipamentos de Segurança | C10: 1 | D10: 32 | E10: 33
B11: Gerir PGR | C11: 3 | D11: 133 | E11: 136
B12: Gerir Prontidão, Emergência e Contingência | C12: 37 | D12: 22 | E12: 59
B13: Gerir Requisitos Legais - CIPLAT | C13: 51 | E13: 51
B14: Gerir Requisitos Legais - NR-35 e NR-37 | C14: 6 | D14: 77 | E14: 83
B15: Gerir Requisitos Legais - Seg. Química | C15: 2 | D15: 31 | E15: 33
B16: Gerir Requisitos Legais - NR-34 | D16: 7 | E16: 7
B17: Total Geral | C17: 113 | D17: 386 | E17: 499
B19: Rótulos de Linha | C19: Não Revisitada | D19: Revisitada
B20: Abrangência | C20: 1 | E20: 1
B21: Gerir Anomalias de SMS | C21: 3 | D21: 11 | E21: 14
B22: Gerir Ergonomia | C22: 9 | D22: 24 | E22: 33
B23: Gerir Higiene Ocupacional | D23: 49 | E23: 49
B24: Gerir M&I de Equipamentos de Segurança | C24: 1 | D24: 32 | E24: 33
B25: Gerir PGR | C25: 3 | D25: 133 | E25: 136
B26: Gerir Prontidão, Emergência e Contingência | C26: 37 | D26: 22 | E26: 59
B27: Gerir Requisitos Legais - CIPLAT | C27: 51 | E27: 51
B28: Gerir Requisitos Legais - NR-35 e NR-37 | C28: 6 | D28: 77 | E28: 83
B29: Gerir Requisitos Legais - Seg. Química | C29: 2 | D29: 31 | E29: 33
B30: Gerir Requisitos Legais - NR-34 | D30: 7 | E30: 7
B31: Total Geral | C31: 113 | D31: 386 | E31: 499
B35: Rótulos de Linha | C35: Contagem de Situação - ATIVO I
B36: Devolver | C36: 22
B37: Não Respondida | C37: 113
B38: Respondida | C38: 387
B39: Transferir | C39: 90
B40: Abrir RTA | C40: 3
B41: Total Geral | C41: 615
B42: Não Revisitada | C42: 113
B43: Revisitada | C43: 387
B44: Análise de Responsabilidade | C44: 112
B45: Abrir RTA | C45: 3
B59: Rótulos de Linha | C59: Contagem de Situação - ATIVO I | D59: Contagem de Processo SEG
...

Sheet Evidências
B2: Obrigação - 83749 - Fabio Mota
B4: ISA PBR-2025-0016584 - https://petrobrasbr.sharepoint.com/:f:/r/teams/bdoc_20240301023456/Documentos%20Compartilhados/2%20-%20Interna/06%20-%20Requisitos%20Legais%20de%20SMS/Gest%C3%A3o%20VCL/Evid%C3%AAncia%20de%20Obriga%C3%A7%C3%B5es%20VCL/Ciclo%20de%20Revisita%C3%A7%C3%A3o%202025-2026/Obriga%C3%A7%C3%A3o%20-%2083749%20-%20Fabio%20Mota?csf=1&web=1&e=XDMbiP
B43: Obrigação - 80273 - Fernando Rodrigues
C45: Sertec - CT-ENGP-EN-009-2024 rev.0 - https://petrobrasbr.sharepoint.com/:b:/r/teams/bdoc_20240301023456/Documentos%20Compartilhados/2%20-%20Interna/06%20-%20Requisitos%20Legais%20de%20SMS/Gest%C3%A3o%20VCL/Evid%C3%AAncia%20de%20Obriga%C3%A7%C3%B5es%20VCL/Ciclo%20de%20Revisita%C3%A7%C3%A3o%202025-2026/Obriga%C3%A7%C3%A3o%20-%2080273%20-%20Fernando%20Rodrigues/CT-ENGP-EN-009-2024_rev.0_assinado%20(1).pdf?csf=1&web=1&e=45exQ4
B146: Obrigação - 52495 - Fabio Mota
B186: Obrigação - 83806 - Fabio Mota
B188: Obrigação - 83806 - Fabio Mota
B190: OBS: Deverá ser emitido novo ISA para RT da NR-33 e resposta ser atualizada
B231: Obrigação - 107137 / 107154 /106842/ 53076/ 107056- Larissa Valois-FIUX
B258: Obrigações 80207 E 80223 - Fernando
B310: Obrigação 80556 - Fernando

Sheet CICLO 2025-2026
B1: Código Obrigação | C1: Validado? | D1: Obrigação | E1: Requisito de SMS | F1: Ementa | G1: Artigo/Item | H1: Assunto | I1: Situação Obrigação | J1: Resposta Anterior | K1: Resposta Ciclo 2025/2026 - ATIVO I | L1: Link Evidência - ATIVO I | M1: Resposta Ciclo 2025/2026 - ATIVO II | N1: Link Evidência - ATIVO II | O1: Processo SEG | P1: Situação - ATIVO I | Q1: Situação - ATIVO II | R1: Responsável pela Resposta no Ciclo | S1: Data Atualização Anterior | T1: Data da Última Atualização | U1: Observação | V1: Análise resposta | W1: Ok? | X1: Observações - Fernanda | Y1: Observações - Sandra | Z1: Observações - Pri
B2: 92673 | D2: A partir da implantação em meio digital do PPP ou de documento que venha a substituí-lo, esse formulário é preenchido para todos os segurados empregados, avulsos e cooperados vinculados a cooperativas de trabalho ou de produção, independentemente do ramo de atividade da empresa, da exposição a agentes prejudiciais à saúde? | E2: INSTRUÇÃO NORMATIVA PRES/INSS Nº 128, DE 28 DE MARÇO DE 2022 | F2: Disciplina as regras, procedimentos e rotinas necessárias à efetiva aplicação das normas de direito previdenciário. | G2: Art. 284, § 1º | H2: RISCOS - Promover a redução e prevenção dos riscos no ambiente do trabalho | I2: Conforme | J2: A emissão via eSocial tem seus dados ambientais extraídos do SIS - Sistema Informatizado de Saúde, para preenchimento automatizado do PPP Digital, e tem seu fluxo descrito no Anexo D.2, do padrão PP-1PBR-00438, gerido pelo SMS/ECES/HOE Walter Motta- F49B | K2: Sim. Conforme previsto no Anexo D, do padrão PP-1PBR-00438- GERIR HIGIENE OCUPACIONAL | L2: PP-1PBR-00438: https://sinpep.petrobras.com.br/SINPEP_Padrao_Web/PadraoEditar?PadraoId=1432# | M2: Sim. Conforme previsto no Anexo D, do padrão PP-1PBR-00438 | N2: PP-1PBR-00438: https://sinpep.petrobras.com.br/SINPEP_Padrao_Web/PadraoEditar?PadraoId=1432# | O2: Gerir Higiene Ocupacional | P2: Respondida | Q2: Respondida | R2: Walter Motta- F49B | S2: 10/4/2025 | T2: 46003 | V2: Analisado | W2: FALSE | Y2: =VLOOKUP($B2,'Rascunho - PRI'!B1:X603,23,FALSE) -> 0 | Z2: Sim. A partir da implantação do PPP em meio digital, o formulário passa a ser preenchido para todos os segurados — empregados, avulsos e cooperados de cooperativas de trabalho ou de produção — independentemente: do ramo de atividade da empresa; e da existência ou não de exposição a agentes prejudiciais à saúde. Conforme previsto no Anexo D do padrão PP‑1PBR‑00438.
B3: 82309 | D3: A empresa elabora e mantém atualizado o PPP para os seus funcionários, bem como fornece o mesmo nas situações elencadas abaixo: I - por ocasião da rescisão do contrato de trabalho ou da desfiliação da cooperativa, sindicato ou órgão gestor de mão de obra, com fornecimento de uma das vias para o trabalhador, mediante recibo; II - sempre que solicitado pelo trabalhador, para fins de requerimento de reconhecimento de períodos laborados em condições especiais; III - para fins de análise de benefícios e serviços previdenciários e quando solicitado pelo INSS; IV - para simples conferência por parte do trabalhador, quando da revisão do Programa de Gerenciamento de Riscos - PGR; e V - quando solicitado pelas autoridades competentes? | E3: INSTRUÇÃO NORMATIVA PRES/INSS Nº 128, DE 28 DE MARÇO DE 2022 | F3: Disciplina as regras, procedimentos e rotinas necessárias à efetiva aplicação das normas de direito previdenciário. | G3: Art. 284, § 5º | H3: RISCOS - Promover a redução e prevenção dos riscos no ambiente do trabalho | I3: Conforme | J3: "O fluxo para emissão (I), solicitação (II, III, IV e V) é atendido, conforme descrito nos itens 3.2 e 3.3, alineas ""a"" e ""b"" do Padrão PE-1PBR-00852, gerido pelo RH/RBO/PB. O processo para solicitação e emissão é descrito no item 3.13 do padrão PE-1PBR-01151, e auditado pelo Serviços de Relações de Trabalho, do Centro de Operações de RH e Atendimento" Walter Motta Junior- F49B | K3: Sim. O fluxo para emissão (I), solicitação (II, III, IV e V) é atendido, conforme descrito nos itens 3.2 e 3.3, alineas ""a"" e ""b"" do Padrão PE-1PBR-00852- EMITIR PERFIL PROFISSIOGRÁFICO PREVIDENCIÁRIO (PPP), gerido pelo RH/RBO/PB. O processo para solicitação e emissão é descrito no item 3.13 do padrão PE-1PBR-01151-GERIR PERFIL PROFISSIOGRÁFICO PREVIDENCIÁRIO - PPP, e auditado pelo Serviços de Relações de Trabalho, do Centro de Operações de RH e Atendimento | L3: PE-1PBR-00852: https://sinpep.petrobras.com.br/SINPEP_Padrao_Web/PadraoEditar?TipoBusca=ONLINE&PadraoId=2601 PE-1PBR-01151: https://sinpep.petrobras.com.br/SINPEP_Padrao_Web/PadraoEditar?PadraoId=1530 | M3: Sim. O fluxo para emissão (I), solicitação (II, III, IV e V) é atendido, conforme descrito nos itens 3.2 e 3.3, alineas ""a"" e ""b"" do Padrão PE-1PBR-00852, gerido pelo RH/RBO/PB. O processo para solicitação e emissão é descrito no item 3.13 do padrão PE-1PBR-01151, e auditado pelo Serviços de Relações de Trabalho, do Centro de Operações de RH e Atendimento | N3: PE-1PBR-00852: https://sinpep.petrobras.com.br/SINPEP_Padrao_Web/PadraoEditar?TipoBusca=ONLINE&PadraoId=2601 PE-1PBR-01151: https://sinpep.petrobras.com.br/SINPEP_Padrao_Web/PadraoEditar?PadraoId=1530 | O3: Gerir Higiene Ocupacional | P3: Respondida | Q3: Respondida | R3: Walter Motta- F49B | S3: 10/4/2025 | T3: 46003 | V3: Analisado | W3: TRUE | Y3: =VLOOKUP($B3,'Rascunho - PRI'!B2:X604,23,FALSE) -> 0 | Z3: ok.
B4: 82381 | D4: A empresa, quando da emissão do LTCAT, observa os elementos informativos exigidos por esta Instrução Normativa? NOTA: Art 276, I - se individual ou coletivo; II - identificação da empresa; III - identificação do setor e da função; IV - descrição da atividade; V - identificação do agente prejudicial à saúde, arrolado na Legislação Previdenciária; VI - localização das possíveis fontes geradoras; VII - via e periodicidade de exposição ao agente prejudicial à saúde; VIII - metodologia e procedimentos de avaliação do agente prejudicial à saúde; IX - descrição das medidas de controle existentes; X - conclusão do LTCAT; XI - assinatura e identificação do médico do trabalho ou engenheiro de segurança do trabalho; e XII - data da realização da avaliação ambiental. IX - descrição das medidas de controle existentes; X - conclusão do LTCAT; XI - assinatura e identificação do médico do trabalho ou engenheiro de segurança do trabalho; e XII - data da realização da avaliação ambiental. | E4: INSTRUÇÃO NORMATIVA PRES/INSS Nº 128, DE 28 DE MARÇO DE 2022 | F4: Disciplina as regras, procedimentos e rotinas necessárias à efetiva aplicação das normas de direito previdenciário. | G4: Art. 276 | H4: RISCOS - Promover a redução e prevenção dos riscos no ambiente do trabalho | I4: Conforme | J4: Os LTCAT são elaborados e emitidos, observando os itens de I a XI, por Demanda Judicial, Exigência do INSS ou Solicitação a Ouvidoria._x000D_ Evidenciando durante a VCL o atendimento a obrigação legal. | K4: Sim. Os LTCAT são elaborados e emitidos, observando os itens de I a XI, por Demanda Judicial, Exigência do INSS ou Solicitação a Ouvidoria, confrome determinado no Manual anexo ao Padrão PE-1PBR-001151- GERIR PERFIL PROFISSIOGRÁFICO PREVIDENCIÁRIO - PPP. | L4: Padrão PE-1PBR-001151: https://sinpep.petrobras.com.br/SINPEP_Padrao_Web/PadraoEditar?TipoBusca=ONLINE&PadraoId=1530 | M4: Sim. Os LTCAT são elaborados e emitidos, observando os itens de I a XI, por Demanda Judicial, Exigência do INSS ou Solicitação a Ouvidoria, confrome determinado no Manual anexo ao Padrão PE-1PBR-001151. | N4: Padrão PE-1PBR-001151: https://sinpep.petrobras.com.br/SINPEP_Padrao_Web/PadraoEditar?TipoBusca=ONLINE&PadraoId=1530 | O4: Gerir Higiene Ocupacional | P4: Respondida | Q4: Respondida | R4: Walter Motta- F49B | S4: 27/1/2025 | T4: 46003 | V4: Analisado | W4: TRUE | Y4: =VLOOKUP($B4,'Rascunho - PRI'!B3:X605,23,FALSE) -> 0 | Z4: ok
B5: 53116 | D5: A comprovação da efetiva exposição dos empregados da empresa aos agentes nocivos faz-se mediante emissão do formulário denominado perfil profissiográfico previdenciário, na forma estabelecida pelo Instituto Nacional do Seguro Social, com base em laudo técnico de condições ambientais do trabalho expedido por médico do trabalho ou engenheiro de segurança do trabalho? | E5: DECRETO Nº 3.048, DE 06 DE MAIO DE 1999 | F5: Aprova o Regulamento da Previdência Social, e dá outras providências. | G5: Art. 68, § 2º | H5: RISCOS - Promover a redução e prevenção dos riscos no ambiente do trabalho | I5: Conforme | J5: "A emissão de PPP é realizada com base na profissiografia informada pelo RH, bem como os dados ambientais das Campanhas de PPRA. _x000D_ A elaboração de LTCAT é feita somente para as seguintes situações: Demanda Judicial, Exigência do INSS ou Solicitação pela Ouvidoria, conforme determinado no Padrão PE-1PBR-01151 - GERIR PERFIL PROFISSIOGRÁFICO PREVIDENCIÁRIO - PPP e seu Anexo ""D""." | K5: Sim. A comprovação da efetiva exposição a agentes nocivos é feita conforme determinado no Padrão PE-1PBR-01151 - GERIR PERFIL PROFISSIOGRÁFICO PREVIDENCIÁRIO - PPP e seu Manual (Anexo) | L5: PE-1PBR-001151: https://sinpep.petrobras.com.br/SINPEP_Padrao_Web/PadraoEditar?TipoBusca=ONLINE&PadraoId=1530 | M5: Sim. A comprovação da efetiva exposição a agentes nocivos é feita conforme determinado no Padrão PE-1PBR-01151 - GERIR PERFIL PROFISSIOGRÁFICO PREVIDENCIÁRIO - PPP e seu Manual (Anexo) | N5: PE-1PBR-001151: https://sinpep.petrobras.com.br/SINPEP_Padrao_Web/PadraoEditar?TipoBusca=ONLINE&PadraoId=1530 | O5: Gerir Higiene Ocupacional | P5: Respondida | Q5: Respondida | R5: Walter Motta- F49B | S5: 18/3/2025 | T5: 46003 | V5: Analisado | W5: TRUE | Y5: =VLOOKUP($B5,'Rascunho - PRI'!B4:X606,23,FALSE) -> 0 | Z5: ok
B6: 82382 | D6: A empresa, a partir de 01/01/2004, realiza o preenchimento do formulário PPP de forma individualizada para seus empregados, trabalhadores avulsos e contribuintes individuais cooperados, que trabalhem expostos a agentes prejudiciais à saúde, ainda que não presentes os requisitos para fins de enquadramento de atividade especial, seja pela eficácia dos equipamentos de proteção, coletivos ou individuais, seja por não se caracterizar a permanência? NOTA: A partir da implantação em meio digital do PPP ou de documento que venha a substituí-lo, esse formulário deverá ser preenchido para todos os segurados empregados, avulsos e cooperados vinculados a cooperativas de trabalho ou de produção, independentemente do ramo de atividade da empresa, da exposição a agentes prejudiciais à saúde. | E6: INSTRUÇÃO NORMATIVA PRES/INSS Nº 128, DE 28 DE MARÇO DE 2022 | F6: Disciplina as regras, procedimentos e rotinas necessárias à efetiva aplicação das normas de direito previdenciário. | G6: Art. 284 | H6: RISCOS - Promover a redução e prevenção dos riscos no ambiente do trabalho | I6: Conforme | J6: A Emissão do PPP é realizada individualizadamente, conforme descrito no item 3.13 do padrão PE-1PBR-01151 e atende em seu conteúdo pautado no descrito no item 3.19, do Anexo B - Guia Técnico de Higiene Ocupacional Petrobras, do PP-1PBR-00438 Walter Motta-F49B | K6: Sim. O preenchimento do PPP é feito conforme determinado no Padrão PE-1PBR-01151 - GERIR PERFIL PROFISSIOGRÁFICO PREVIDENCIÁRIO - PPP e seu Manual (Anexo) | L6: PE-1PBR-001151: https://sinpep.petrobras.com.br/SINPEP_Padrao_Web/PadraoEditar?TipoBusca=ONLINE&PadraoId=1530 | M6: Sim. O preenchimento do PPP é feito conforme determinado no Padrão PE-1PBR-01151 - GERIR PERFIL PROFISSIOGRÁFICO PREVIDENCIÁRIO - PPP e seu Manual (Anexo) | N6: PE-1PBR-001151: https://sinpep.petrobras.com.br/SINPEP_Padrao_Web/PadraoEditar?TipoBusca=ONLINE&PadraoId=1530 | O6: Gerir Higiene Ocupacional | P6: Respondida | Q6: Respondida | R6: Walter Motta- F49B | S6: 10/4/2025 | T6: 46003 | V6: Analisado | W6: FALSE | Y6: =VLOOKUP($B6,'Rascunho - PRI'!B5:X607,23,FALSE) -> 0 | Z6: =VLOOKUP($B6,'Rascunho - PRI'!B5:X607,23,FALSE) -> 0
B7: 60217 | D7: A empresa realiza o correto preenchimento do Perfil Profissiográfico Previdenciário - PPP? NOTA 01: A partir do início da obrigatoriedade dos eventos de Segurança e Saúde no Trabalho (SST) no Sistema Simplificado de Escrituração Digital das Obrigações Previdenciárias, Trabalhistas e Fiscais - eSocial, o PPP será emitido exclusivamente em meio eletrônico para os segurados das empresas obrigadas. NOTA 02: O registro da profissiografia relacionada a período anterior deverá ser feito conforme procedimento adotado à época, em meio físico. | E7: PORTARIA MTP Nº 313, DE 22 DE SETEMBRO DE 2021 | F7: Dispõe sobre a implantação do Perfil Profissiográfico Previdenciário (PPP) em meio eletrônico, de que tratam os §§ 3º e 8º do art. 68 do Regulamento da Previdência Social, aprovado pelo Decreto nº 3.048, de 6 de maio de 1999, com redação dada pelo Decreto nº 10.410, de 30 de junho de 2020. | G7: Art. 2º | H7: RISCOS - Promover a redução e prevenção dos riscos no ambiente do trabalho | I7: Conforme | J7: "A emissão via eSocial tem seus dados ambientais extraídos do SIS - Sistema Informatizado de Saúde, para preenchimento automatizado do PPP Digital, e tem seu fluxo descrito no Anexo D.2, do padrão PP-1PBR-00438, gerido pelo SMS/ECES/HOE". _x000D_ Poderia ser adicionado "O registro da profissiografia relacionada ao período anterior segue o disposto no item 7.4, Anexo D - Orientações Corporativas para Preenchimento dos Registros Ambientais do Perfil Profissiográfico Previdenciário ¿ PPP ¿ Itens de SMS"_x000D_ Walter Motta- F49B | K7: Sim. Notas 01 e 02 tem seu fluxo descrito no Anexo D, do padrão PP-1PBR-00438 | L7: PP-1PBR-00438: https://sinpep.petrobras.com.br/SINPEP_Padrao_Web/PadraoEditar?PadraoId=1432# | M7: Sim. Notas 01 e 02 tem seu fluxo descrito no Anexo D, do padrão PP-1PBR-00438 | N7: PP-1PBR-00438: https://sinpep.petrobras.com.br/SINPEP_Padrao_Web/PadraoEditar?PadraoId=1432# | O7: Gerir Higiene Ocupacional | P7: Respondida | Q7: Respondida | R7: Walter Motta- F49B | S7: 9/5/2025 | T7: 46003 | W7: FALSE | Y7: =VLOOKUP($B7,'Rascunho - PRI'!B6:X608,23,FALSE) -> 0 | Z7: =VLOOKUP($B7,'Rascunho - PRI'!B6:X608,23,FALSE) -> 0
B8: 51479 | D8: Os exercícios simulados de emergência são programados periodicamente de forma a contemplar os cenários previstos no Plano de Resposta a Emergência de acordo com os riscos envolvidos e a complexidade do Sistema Submarino; Coordenados com as partes envolvidas e autoridades competentes; Avaliados de forma a identificar as irregularidades e oportunidades de melhoria? | E8: RESOLUÇÃO ANP Nº 41, DE 09 DE OUTUBRO DE 2015 | F8: Aprova o Regulamento Técnico do Sistema de Gerenciamento de Segurança Operacional de Sistemas Submarinos - SGSS. | G8: Anexo Item 18.5.1 | H8: SEGURANÇA OPERACIONAL - Sistemas Submarinos | I8: Conforme | J8: PE-2SMS-00074 GERIR TREINAMENTOS DE CONTINGÊNCIA E SIMULADOS NO E&P UN-BUZ SMS SEG - Documentos\2 - Interna\04 - Contingência, Prontidão e Resposta\01. Simulados\01 - Simulado N1 Sistema: Portal de Gestão / BDoc Sandra Nery- LNGH | O8: Gerir Prontidão, Emergência e Contingência | P8: Não Respondida | Q8: Não Respondida | R8: Walcy Borges- SESM | S8: 30/5/2025 | W8: FALSE | Y8: =VLOOKUP($B8,'Rascunho - PRI'!B7:X609,23,FALSE) -> 0 | Z8: =VLOOKUP($B8,'Rascunho - PRI'!B7:X609,23,FALSE) -> 0
B9: 51481 | D9: Foi elaborado procedimento para emissão de permissão de trabalho, contendo no mínimo, o estabelecimento dos tipos de atividade que possam constituir riscos para a segurança operacional; A necessidade da análise prévia das condições de segurança para execução de tarefas, bem como dos perigos existentes; A inclusão na permissão de trabalho, do seu prazo de validade e de medidas adicionais de precaução e mitigação; Estabelecimento de responsabilidades e atribuições para a Força de Trabalho responsável por emitir e aprovar as permissões de trabalho; necessidade de treinamento; e Definição de metodologia de arquivamento para cada tipo de permissão de trabalho, considerando prazos compatíveis com a relevância do serviço executado? | E9: RESOLUÇÃO ANP Nº 41, DE 09 DE OUTUBRO DE 2015 | F9: Aprova o Regulamento Técnico do Sistema de Gerenciamento de Segurança Operacional de Sistemas Submarinos - SGSS. | G9: Anexo Item 19.2 | H9: SEGURANÇA OPERACIONAL - Sistemas Submarinos | I9: Conforme | J9: PE-1PBR-00210- MS- PERMISSÃO PARA TRABALHO Sistema: Portal de Gestão Sandra Nery- LNGH | O9: Gerir Prontidão, Emergência e Contingência | P9: Não Respondida | Q9: Não Respondida | R9: Walcy Borges- SESM | S9: 30/5/2025 | W9: FALSE | Y9: =VLOOKUP($B9,'Rascunho - PRI'!B8:X610,23,FALSE) -> 0 | Z9: =VLOOKUP($B9,'Rascunho - PRI'!B8:X610,23,FALSE) -> 0
B10: 51639 | D10: O Operador do Contrato define e documenta os valores e a política de segurança operacional, seu comprometimento e obrigações para proteção da vida humana, do meio ambiente e das atividades econômicas próprias e de terceiros, sendo estes documentos aprovados pela alta gerência? | E10: RESOLUÇÃO ANP Nº 46, DE 01 DE NOVEMBRO DE 2016 | F10: Aprova o Regime de Segurança Operacional para Integridade de Poços de Petróleo e Gás Natural, que estabelece os requisitos de segurança operacional e de preservação do meio ambiente para perfuração, completação, avaliação, intervenção, produção e abandono de poços de petróleo e gás natural. | G10: Item 1.2 | H10: SEGURANÇA OPERACIONAL - Integridade de Poços | I10: Conforme | J10: "PL-0SPB-00002 POLÍTICA DE SEGURANÇA, MEIO AMBIENTE E SAÚDE - SMS https://portal.petrobras.com.br/sobre-nos/nossa-estrategia https://portal.petrobras.com.br/sustentabilidade-e-seguranca/seguranca Sistema:Portal de Gestão / Intranet Atendido conforme padrão PL-0SPB-00002 - POLÍTICA DE SEGURANÇA, MEIO AMBIENTE E SAÚDE - SMS disponível no portal de gestão." Sandra Nery-LNGH | O10: Gerir Prontidão, Emergência e Contingência | P10: Não Respondida | Q10: Não Respondida | R10: Walcy Borges- SESM | S10: 30/5/2025 | W10: FALSE | Y10: =VLOOKUP($B10,'Rascunho - PRI'!B9:X611,23,FALSE) -> 0 | Z10: =VLOOKUP($B10,'Rascunho - PRI'!B9:X611,23,FALSE) -> 0
B11: 54316 | D11: Na elaboração do Plano de Emergência Individual foram observadas as diretrizes trazidas pela presente Nota Técnica? | E11: NOTA TÉCNICA CGPEG/DILIC/IBAMA Nº 03, DE 20 DE SETEMBRO DE 2013 | F11: Diretrizes para aprovação dos Planos de Emergência Individual ¿ PEI, nos processos de licenciamento ambiental dos empreendimentos marítimos de exploração e produção de petróleo e gás natural. | G11: Item I | H11: RECURSOS HÍDRICOS - Controle de poluição por óleo e outras substâncias nocivas/perigosas em águas jurisdicionais brasileiras OFFSHORE | I11: Conforme | J11: Conforme procedimentos e obtenção de L.O PE-3BUZ-00219 PEI - PLANO DE EMERGÊNCIA INDIVIDUAL DA PLATAFORMA P-74 PE-3BUZ-00220 PEI - PLANO DE EMERGÊNCIA INDIVIDUAL DA PLATAFORMA P-75 PE-3BUZ-00221 PEI - PLANO DE EMERGÊNCIA INDIVIDUAL DA PLATAFORMA P-76 PE-3BUZ-00222 PEI - PLANO DE EMERGÊNCIA INDIVIDUAL DA PLATAFORMA P-77 Sistema: Portal de Gestão Walcy Borges- SESM | K11: Conforme procedimentos e obtenção de L.O PE-3BUZ-00219 PEI - PLANO DE EMERGÊNCIA INDIVIDUAL DA PLATAFORMA P-74 PE-3BUZ-00220 PEI - PLANO DE EMERGÊNCIA INDIVIDUAL DA PLATAFORMA P-75 PE-3BUZ-00221 PEI - PLANO DE EMERGÊNCIA INDIVIDUAL DA PLATAFORMA P-76 PE-3BUZ-00222 PEI - PLANO DE EMERGÊNCIA INDIVIDUAL DA PLATAFORMA P-77 | L11: Portal de Gestão | M11: Conforme procedimentos e obtenção de L.O PE-3BUZ-00219 PEI - PLANO DE EMERGÊNCIA INDIVIDUAL DA PLATAFORMA P-74 PE-3BUZ-00220 PEI - PLANO DE EMERGÊNCIA INDIVIDUAL DA PLATAFORMA P-75 PE-3BUZ-00221 PEI - PLANO DE EMERGÊNCIA INDIVIDUAL DA PLATAFORMA P-76 PE-3BUZ-00222 PEI - PLANO DE EMERGÊNCIA INDIVIDUAL DA PLATAFORMA P-77 | N11: Portal de Gestão | O11: Gerir Prontidão, Emergência e Contingência | P11: Respondida | Q11: Respondida | R11: Walcy Borges- SESM | S11: 8/5/2025 | T11: 46050 | W11: FALSE | Y11: =VLOOKUP($B11,'Rascunho - PRI'!B10:X612,23,FALSE) -> 0 | Z11: =VLOOKUP($B11,'Rascunho - PRI'!B10:X612,23,FALSE) -> 0
B12: 92186 | D12: Após a realização dos exercícios simulados ou na ocorrência de situações reais, é elaborado relatório, com o objetivo de verificar a eficácia do PRE, detectar possíveis falhas e subsidiar os ajustes necessários? | E12: NR-34 | F12: CONDIÇÕES E MEIO AMBIENTE DE TRABALHO NA INDÚSTRIA DA CONSTRUÇÃO,REPARAÇÃO E DESMONTE NAVAL. | G12: Item 34.17.4.2 | H12: ATIVIDADES OFFSHORE - AMBIENTE NAVAL | I12: Conforme | J12: Sim, Relatórios disponíveis na endereço: UN-BUZ SMS SEG - Documentos\2 - Interna\04 - Contingência, Prontidão e Resposta\01. Simulados\01 - Simulado N1 Sistema: BDOC Walcy Borges- SESM | K12: Sim, após a realização dos simulados ou ocorrências reais são emitidos relatórios | L12: Relatórios disponiveis na endereço UN-BUZ SMS SEG - Documentos\2 - Interna\04 - Contingência, Prontidão e Resposta\01. Simulados\01 - Simulado N1 | M12: Sim, após a realização dos simulados ou ocorrências reais são emitidos relatórios | N12: Relatórios disponiveis na endereço UN-BUZ SMS SEG - Documentos\2 - Interna\04 - Contingência, Prontidão e Resposta\01. Simulados\01 - Simulado N1 | O12: Gerir Prontidão, Emergência e Contingência | P12: Respondida | Q12: Respondida | R12: Walcy Borges- SESM | S12: 8/5/2025 | T12: 46050 | W12: FALSE | Y12: =VLOOKUP($B12,'Rascunho - PRI'!B11:X613,23,FALSE) -> 0 | Z12: =VLOOKUP($B12,'Rascunho - PRI'!B11:X613,23,FALSE) -> 0
B13: 51416 | D13: O Operador do Sistema Submarino criou um banco de dados com os Alertas de Segurança recebidos e emitidos, avalia a aplicabilidade dos Alertas de Segurança recebidos e implementa as ações pertinentes compatíveis com os riscos envolvidos (conforme itens 11.3.3.2 e 11.3.3.3)? | E13: RESOLUÇÃO ANP Nº 41, DE 09 DE OUTUBRO DE 2015 | F13: Aprova o Regulamento Técnico do Sistema de Gerenciamento de Segurança Operacional de Sistemas Submarinos - SGSS. | G13: Anexo Item 11.4 | H13: SEGURANÇA OPERACIONAL - Sistemas Submarinos | I13: Conforme | J13: Sistema: Intranet (https://portal.petrobras.com.br/group/portal-petrobras/sustentabilidade-e-seguranca/seguranca) / Abrange+ Sandra Nery- LNGH | O13: Gerir Prontidão, Emergência e Contingência | P13: Não Respondida | Q13: Não Respondida | R13: Walcy Borges- SESM | S13: 30/5/2025 | W13: FALSE | Y13: =VLOOKUP($B13,'Rascunho - PRI'!B12:X614,23,FALSE) -> 0 | Z13: =VLOOKUP($B13,'Rascunho - PRI'!B12:X614,23,FALSE) -> 0
B14: 51448 | D14: O Plano de Resposta a Emergência é reavaliado periodicamente, sempre que necessário e, no mínimo, nas seguintes situações: sempre que uma análise de riscos assim o indicar; sempre que ocorrerem modificações físicas, operacionais ou organizacionais que afetem os seus procedimentos ou a sua capacidade de resposta; quando a avaliação do desempenho do Plano de Resposta a Emergência, decorrente do seu acionamento por Incidente ou exercício simulado, recomendar; e em outras situações a critério da ANP? | E14: RESOLUÇÃO ANP Nº 41, DE 09 DE OUTUBRO DE 2015 | F14: Aprova o Regulamento Técnico do Sistema de Gerenciamento de Segurança Operacional de Sistemas Submarinos - SGSS. | G14: Anexo Item 18.6 | H14: SEGURANÇA OPERACIONAL - Sistemas Submarinos | I14: Conforme | J14: Conforme sumário de revisões nos padrões ou sistemas definidos._x000D_ _x000D_ Sistema: Portal de Gestão / INFOPAE_x000D_ Sandra Nery- LNGH | O14: Gerir Prontidão, Emergência e Contingência | P14: Não Respondida | Q14: Não Respondida | R14: Walcy Borges- SESM | S14: 30/5/2025 | W14: FALSE | Y14: =VLOOKUP($B14,'Rascunho - PRI'!B13:X615,23,FALSE) -> 0 | Z14: =VLOOKUP($B14,'Rascunho - PRI'!B13:X615,23,FALSE) -> 0
B15: 51463 | D15: O relatório de investigação do Incidente, contém, no mínimo: a Data do Incidente; Data do início da investigação do Incidente; Introdução, contendo dados técnicos do objeto investigado; Composição da equipe de investigação, incluindo a função, empresa e setor de cada membro participante; Técnicas e ferramentas de investigação de Incidente; Descrição do Incidente; Se o Incidente estiver relacionado a vazamento de produtos perigosos, incluir indicação do volume vazado ou descarregado e o comportamento da mancha; sequência em ordem cronológica de eventos associados ao Incidente, fatores Causais e Causas Raiz, demonstrando a relação com a sequência de eventos; recomendações, enfatizando a importância de sua aplicação; e referências, incluindo os documentos utilizados na investigação, mídias digitais de imagens, vídeos e gravações, conforme aplicável? | E15: RESOLUÇÃO ANP Nº 41, DE 09 DE OUTUBRO DE 2015 | F15: Aprova o Regulamento Técnico do Sistema de Gerenciamento de Segurança Operacional de Sistemas Submarinos - SGSS. | G15: Anexo Item 14.5.2 | H15: SEGURANÇA OPERACIONAL - Sistemas Submarinos | I15: Conforme | J15: "PP-1PBR-00150 - GERIR ANOMALIAS DE SMS._x000D_ _x000D_ Sistema: SAP-SMS"_x000D_ Sandra Nery- LNGH | O15: Gerir Prontidão, Emergência e Contingência | P15: Não Respondida | Q15: Não Respondida | R15: Walcy Borges- SESM | S15: 30/5/2025 | W15: FALSE | Y15: =VLOOKUP($B15,'Rascunho - PRI'!B14:X616,23,FALSE) -> 0 | Z15: =VLOOKUP($B15,'Rascunho - PRI'!B14:X616,23,FALSE) -> 0
B16: 55396 | C16: Sim | D16: A empresa possui um Plano de Emergência prevendo a ocorrência de emergências na área de armazenamento de resíduos perigosos? NOTA: O Plano deve conter os seguintes itens: a) informações de possíveis incidentes e das ações a serem tomadas; b) lista atualizada com indicação da pessoa que deve atuar como coordenador e seu substituto, indicando seus telefones e endereços; c) lista de todos os equipamentos de segurança existentes, incluindo localização, descrição do tipo e capacidade. | E16: ABNT NBR 12235:1992 | F16: Armazenamento de resíduos sólidos perigosos - Procedimento. | G16: Item 5.2 | H16: RESÍDUOS PERIGOSOS - Geração de resíduos perigosos (obrigações gerais) | I16: Conforme | J16: 1- O Plano de Resposta a Emergência das unidades de Búzios PE-3BUZ-00100 prevê ocorrências de emergência na área de armazenamento de resíduos perigosos, contempla cenários emergenciais que podem ser associados aos riscos inerentes á área supracitada. Como por exemplo: Liberação produtos químicos no convés da embarcação. a) No item 13 do PE-3BUZ-00100 estão relacionados os cenários de emergências mapeados para as unidades de Búzios. O Anexo E - Estratégias e Procedimentos Operacionais de Resposta contempla o fluxograma das ações a serem realizadas para o controle das emergências. b) No Anexo C é demonstrada a estrutura da EOR - Estrutura Organizacional de Resposta. A comunicação é realizada conforme item 3.2 do PRE. c) A relação dos equipamentos para contenção e limpeza de produtos químicos vazado, bem como as informações associadas a localização estão contempladas no PEI - Plano de Emergência Individual, onde cada unidade de Búzios possui um padrão individual. PE-3BUZ-00219 - PEI - Plano de Emergência Individual para Incidentes de Poluição por Óleo da P-74 PE-3BUZ-00220 - PEI - Plano de Emergência Individual para Incidentes de Poluição por Óleo da P-75 PE-3BUZ-00221 - PEI - Plano de Emergência Individual para Incidentes de Poluição por Óleo da P-76 PE-3BUZ-00222 - PEI - Plano de Emergência Individual para Incidentes de Poluição por Óleo da P-77 (Leandro) | K16: Sim, os cenários de emergência são contemplados no PRE - Plano de Resposta a Emergência das unidades de Búzios (PE-3BUZ-00100 - PLANO DE RESPOSTA A EMERGÊNCIAS NAS PLATAFORMAS) de acordo com as legislações da ANP, IBAMA, MTE e Marinha. | L16: INFOPAE - https://infopae.petrobras.com.br/ipae/?hxid=50c57e2be46b67df#/main?url= Portal de Gestão - SINPEP: https://portalgestao.petrobras.com.br/pges/#/ | O16: Gerir Prontidão, Emergência e Contingência | P16: Respondida | Q16: Respondida | R16: Walcy Borges- SESM | S16: 21/6/2023 | T16: 45945 | V16: Analisado | W16: FALSE | X16: Padrão fala em como acessar o INFOPAE, não fala sobre Plano de Emergência para ocorrências nas áreas de armazenamento de produtos perigosos. Padrão/Resposta está correto? | Z16: =VLOOKUP($B16,'Rascunho - PRI'!B15:X617,23,FALSE) -> Padrão fala em como acessar o INFOPAE, não fala sobre Plano de Emergência para ocorrências nas áreas de armazenamento de produtos perigosos. Padrão/Resposta está correto?
B17: 80409 | D17: Os exercícios simulados envolvem os trabalhadores designados e contemplam os cenários e a periodicidade definidos no PRE? NOTA: Após a realização dos exercícios simulados ou na ocorrência de sinistros a bordo, deve ser avaliado o atendimento do PRE, com o objetivo de se verificar a sua eficácia, detectar possíveis desvios e proceder aos ajustes necessários. | E17: NR-37 | F17: SEGURANÇA E SAÚDE EM PLATAFORMAS DE PETRÓLEO. | G17: Item 37.28.3.1 | H17: ATIVIDADES OFFSHORE - RESPOSTA A EMERGÊNCIA | I17: Conforme | J17: "Conforme procedimento PE-2SMS-00074 PGERIR TREINAMENTOS DE CONTINGÊNCIA E SIMULADOS NO E&P UN-BUZ SMS SEG - Documentos\2 - Interna\04 - Contingência, Prontidão e Resposta\01. Simulados\01 - Simulado N1 Sistema: Portal de Gestão / BDOC Conforme cronograma de Simulado de Búzios (PE-2SMS-00074)" Walcy Borges- SESM | K17: Conforme procedimento PE-2SMS-00074 PGERIR TREINAMENTOS DE CONTINGÊNCIA E SIMULADOS NO E&P | L17: Portal de Gestão BDOC: UN-BUZ SMS SEG - Documentos\2 - Interna\04 - Contingência, Prontidão e Resposta\01. Simulados\01 - Simulado N1 | M17: Conforme procedimento PE-2SMS-00074 PGERIR TREINAMENTOS DE CONTINGÊNCIA E SIMULADOS NO E&P | N17: Portal de Gestão BDOC: UN-BUZ SMS SEG - Documentos\2 - Interna\04 - Contingência, Prontidão e Resposta\01. Simulados\01 - Simulado N1 | O17: Gerir Prontidão, Emergência e Contingência | P17: Respondida | Q17: Respondida | R17: Walcy Borges- SESM | S17: 8/5/2025 | T17: 46050 | W17: FALSE | Y17: =VLOOKUP($B17,'Rascunho - PRI'!B16:X618,23,FALSE) -> 0 | Z17: =VLOOKUP($B17,'Rascunho - PRI'!B16:X618,23,FALSE) -> 0
B18: 80410 | D18: A operadora da instalação mantém em local visível a tabela atualizada de postos de emergência, relacionando nominalmente os trabalhadores integrantes das equipes que compõem o PRE a bordo? | E18: NR-37 | F18: SEGURANÇA E SAÚDE EM PLATAFORMAS DE PETRÓLEO. | G18: Item 37.28.2.1 | H18: ATIVIDADES OFFSHORE - RESPOSTA A EMERGÊNCIA | I18: Conforme | J18: Listagem disponível na sala de briefing_x000D_ Sistema: APLAT _x000D_ _x000D_ _x000D_ Walcy Borges- SESM | K18: Listagem disponível na sala de briefing | L18: APLAT | M18: Listagem disponível na sala de briefing | N18: APLAT | O18: Gerir Prontidão, Emergência e Contingência | P18: Respondida | Q18: Respondida | R18: Walcy Borges- SESM | S18: 8/5/2025 | T18: 46050 | W18: FALSE | Y18: =VLOOKUP($B18,'Rascunho - PRI'!B17:X619,23,FALSE) -> 0 | Z18: =VLOOKUP($B18,'Rascunho - PRI'!B17:X619,23,FALSE) -> 0
B19: 80583 | D19: A proteção contra incêndios nas plataformas foi desenvolvida por meio de uma abordagem estruturada, considerar os riscos existentes para os trabalhadores, possuindo os objetivos constantes do Item 37.25.2? | E19: NR-37 | F19: SEGURANÇA E SAÚDE EM PLATAFORMAS DE PETRÓLEO. | G19: Item 37.25.2 | H19: ATIVIDADES OFFSHORE - COMBATE E PREVENÇÃO A INCÊNDIOS (GERAL) | I19: Conforme | J19: A proteção contra incêndio é realizada pela SRGE com base na analise de risco e requisitos normativos aplicados a estes sistemas. Alterações posteriores são realizadas por GM - Gerenciamento de mudanças pela Operação. Walcy Borges- SESM | O19: Gerir Prontidão, Emergência e Contingência | P19: Transferir | Q19: Transferir | R19: Walcy Borges- SESM | S19: 2/5/2025 | U19: Responsabilidade das Gerências PDP e SRGE | W19: FALSE | Y19: =VLOOKUP($B19,'Rascunho - PRI'!B18:X620,23,FALSE) -> 0 | Z19: =VLOOKUP($B19,'Rascunho - PRI'!B18:X620,23,FALSE) -> 0
B20: 51431 | D20: Foi elaborado, implementado e documentado procedimentos e métodos para monitorar e medir regularmente as características principais das operações e atividades que possam causar acidentes, incluindo o registro das informações, o método de acompanhamento do desempenho, os controles operacionais pertinentes, a conformidade com as metas e objetivos de segurança operacional e a periodicidade de medição e controle? NOTA: É obrigatório a designação de um responsável pelo acompanhamento de cada Indicador de Desempenho. | E20: RESOLUÇÃO ANP Nº 41, DE 09 DE OUTUBRO DE 2015 | F20: Aprova o Regulamento Técnico do Sistema de Gerenciamento de Segurança Operacional de Sistemas Submarinos - SGSS. | G20: Anexo Item 11.3.1 e 11.3.1.1 | H20: SEGURANÇA OPERACIONAL - Sistemas Submarinos | I20: Conforme | J20: DI-1PBR-00125 - DIRETRIZES PARA O GERENCIAMENTO DA INTEGRIDADE DE SISTEMAS SUBMARINOS NA PETROBRAS Sistema: Portal de Gestão Sandra Nery- LNGH | O20: Gerir Prontidão, Emergência e Contingência | P20: Não Respondida | Q20: Não Respondida | R20: Walcy Borges- SESM | S20: 30/5/2025 | W20: FALSE | Y20: =VLOOKUP($B20,'Rascunho - PRI'!B19:X621,23,FALSE) -> 0 | Z20: =VLOOKUP($B20,'Rascunho - PRI'!B19:X621,23,FALSE) -> 0
B21: 51591 | D21: O Plano de Emergência é reavaliado sempre que uma análise de risco assim o indicar; quando a avaliação do desempenho do Plano de Emergência, decorrente do seu acionamento por incidente ou exercício simulado, recomendar; sempre que a instalação sofrer modificações físicas, operacionais ou organizacionais que afetem seus procedimentos ou a sua capacidade de resposta; ou em outras situações a critério da ANP? | E21: RESOLUÇÃO ANP Nº 43, DE 06 DE DEZEMBRO DE 2007 | F21: Institui o Regime de Segurança Operacional para as Instalações de Perfuração e Produção de Petróleo e Gás Natural. | G21: Prática de Gestão 14 - Item 14.7 | H21: SEGURANÇA OPERACIONAL - Atividade de Operação e Produção Marítima | I21: Conforme | J21: Sim. Conforme os padrões PE-3BUZ-00100 - PLANO DE RESPOSTA A EMERGÊNCIAS NAS PLATAFORMAS, PE-3BUZ-00222 - PEI - PLANO DE EMERGÊNCIA INDIVIDUAL DA PLATAFORMA P-77, PE-3BUZ-00220 - PEI - PLANO DE EMERGÊNCIA INDIVIDUAL DA PLATAFORMA P-75, PE-3BUZ-00219 - PEI - PLANO DE EMERGÊNCIA INDIVIDUAL DA PLATAFORMA P-74 e PE-3BUZ-00221 - PEI - PLANO DE EMERGÊNCIA INDIVIDUAL DA PLATAFORMA P-76. _x000D_ Fabio Mota- DXV9 | O21: Gerir Prontidão, Emergência e Contingência | P21: Não Respondida | Q21: Não Respondida | R21: Walcy Borges- SESM | S21: 23/5/2025 | W21: FALSE | Y21: =VLOOKUP($B21,'Rascunho - PRI'!B20:X622,23,FALSE) -> 0 | Z21: =VLOOKUP($B21,'Rascunho - PRI'!B20:X622,23,FALSE) -> 0
B22: 51599 | D22: Operador do Contrato designa a equipe responsável e inicia os trabalhos de investigação tão rapidamente quanto possível, não excedendo 48 horas após o encerramento do incidente, a fim de preservar as evidências, salvo por motivo de força maior devidamente justificado e documentado? | E22: RESOLUÇÃO ANP Nº 46, DE 01 DE NOVEMBRO DE 2016 | F22: Aprova o Regime de Segurança Operacional para Integridade de Poços de Petróleo e Gás Natural, que estabelece os requisitos de segurança operacional e de preservação do meio ambiente para perfuração, completação, avaliação, intervenção, produção e abandono de poços de petróleo e gás natural. | G22: Item 9.4.1 | H22: SEGURANÇA OPERACIONAL - Integridade de Poços | I22: Conforme | J22: Sim, conforme PP-1PBR-00150 GERIR ANOMALIAS DE SMS Sistema: SAP SMS Sandra Nery- LNGH | O22: Gerir Prontidão, Emergência e Contingência | P22: Não Respondida | Q22: Não Respondida | R22: Walcy Borges- SESM | S22: 30/5/2025 | W22: FALSE | Y22: =VLOOKUP($B22,'Rascunho - PRI'!B21:X623,23,FALSE) -> 0 | Z22: =VLOOKUP($B22,'Rascunho - PRI'!B21:X623,23,FALSE) -> 0
B23: 51631 | D23: Foi elaborado procedimentos de controle abordando a identificação de novos perigos introduzidos pelas Operações Simultâneas e verificação da existência de medidas de prevenção e/ou mitigação adequadas para estes perigos; definição das responsabilidades, de modo a assegurar uma adequada coordenação entre todas as organizações envolvidas, incluindo resposta à emergência? | E23: RESOLUÇÃO ANP Nº 43, DE 06 DE DEZEMBRO DE 2007 | F23: Institui o Regime de Segurança Operacional para as Instalações de Perfuração e Produção de Petróleo e Gás Natural. | G23: Prática de Gestão 15 - Item 15.4 | H23: SEGURANÇA OPERACIONAL - Atividade de Operação e Produção Marítima | I23: Conforme | J23: Sim, conforme PE-1PBR-00211 - MS- TRABALHOS E OPERAÇÕES SIMULTÂNEAS.Sistema Portal de Gestão.Sandra Nery | O23: Gerir Prontidão, Emergência e Contingência | P23: Não Respondida | Q23: Não Respondida | R23: Walcy Borges- SESM | S23: 9/6/2025 | W23: FALSE | Y23: =VLOOKUP($B23,'Rascunho - PRI'!B22:X624,23,FALSE) -> 0 | Z23: =VLOOKUP($B23,'Rascunho - PRI'!B22:X624,23,FALSE) -> 0
B24: 52071 | D24: A unidade providenciou para todos os trabalhadores informações sobre: utilização dos equipamentos de combate ao incêndio; procedimentos de resposta aos cenários de emergências e para evacuação dos locais de trabalho com segurança; e dispositivos de alarme existentes? | E24: NR-23 | F24: PROTEÇÃO CONTRA INCÊNDIO. | G24: Item 23.3.2 | H24: INCÊNDIO E EXPLOSÃO / PREVENÇÃO - Obrigações gerais relativas à combate e prevenção a INCÊNDIOS | I24: Conforme | J24: Sim, Através de treinamento básico da NR-37, briefings de segurança para toda a força de trabalho e CBSP. Em treinamentos específicos para atuação na EOR. Sistema: SIRH Walcy Borges- SESM | K24: Através de treinamento básico da NR-37, briefings de segurança para toda a força de trabalho e CBSP | L24: Em treinamentos especificos para atuação na EOR. Sistema: SIRH | M24: Através de treinamento básico da NR-37, briefings de segurança para toda a força de trabalho e CBSP | N24: Em treinamentos especificos para atuação na EOR. Sistema: SIRH | O24: Gerir Prontidão, Emergência e Contingência | P24: Respondida | Q24: Respondida | R24: Walcy Borges- SESM | S24: 8/5/2025 | T24: 46050 | W24: FALSE | Y24: =VLOOKUP($B24,'Rascunho - PRI'!B23:X625,23,FALSE) -> 0 | Z24: =VLOOKUP($B24,'Rascunho - PRI'!B23:X625,23,FALSE) -> 0
B25: 53658 | D25: 1 - A aplicação de dispersantes químicos, como técnica de resposta a incidentes de poluição por óleo, somente é utilizada quando a não intervenção ou a aplicação de técnicas mecânicas de contenção, recolhimento e dispersão se mostrarem não efetivas, inaplicáveis ou insuficientes? 2 - O disposto anteriormente não se aplica quando for necessária a adoção de medidas emergenciais para situações de risco iminente de incêndio ou de salvaguarda da vida humana no mar, envolvendo instalações marítimas ou navios. | E25: RESOLUÇÃO CONAMA Nº 472, DE 27 DE NOVEMBRO DE 2015 | F25: Dispõe sobre o uso de dispersantes químicos em incidentes de poluição por óleo no mar. | G25: Art. 5º | H25: RECURSOS HÍDRICOS - Controle de poluição por óleo e outras substâncias nocivas/perigosas em águas jurisdicionais brasileiras OFFSHORE | I25: Conforme | J25: Conforme procedimento PE-3UBS-00627 PEVO-BS - PLANO DE EMERGÊNCIA PARA VAZAMENTO DE ÓLEO NA ÁREA GEOGRÁFICA DA BACIA DE SANTOS Sistema: Portal de Gestão Walcy Borges- SESM | K25: Conforme procedimento PE-3UBS-00627 PEVO-BS - PLANO DE EMERGÊNCIA PARA VAZAMENTO DE ÓLEO NA ÁREA GEOGRÁFICA DA BACIA DE SANTOS | L25: Portal de Gestão | M25: Conforme procedimento PE-3UBS-00627 PEVO-BS - PLANO DE EMERGÊNCIA PARA VAZAMENTO DE ÓLEO NA ÁREA GEOGRÁFICA DA BACIA DE SANTOS | N25: Portal de Gestão | O25: Gerir Prontidão, Emergência e Contingência | P25: Respondida | Q25: Respondida | R25: Walcy Borges- SESM | S25: 8/5/2025 | T25: 46050 | W25: FALSE | Y25: =VLOOKUP($B25,'Rascunho - PRI'!B24:X626,23,FALSE) -> 0 | Z25: =VLOOKUP($B25,'Rascunho - PRI'!B24:X626,23,FALSE) -> 0
B26: 107203 | D26: Foi elaborado plano de emergência incluindo informações sobre o que fazer no caso de incêndio, acidente, incidentes e emissões e/ou vazamentos de produtos químicos, além das informações mínimas descritas nos itens 7.4.2, 7.4.3, 7.4.4? | E26: ABNT NBR 17160:2024 | F26: Armazenamento seguro de produtos químicos. | G26: Item 7.4 | H26: PRODUTOS QUÍMICOS - Utilizar PRODUTOS QUÍMICOS em geral (obrigações gerais) | I26: Conforme | J26: Sim, as plataformas possuem o Plano de Resposta a Emergência (PRE) contemplando ações em caso de incêndio, acidente, incidentes e emissões e/ou vazamentos de produtos químicos. - Fábio Mota-DXV9 | O26: Gerir Prontidão, Emergência e Contingência | P26: Não Respondida | Q26: Não Respondida | R26: Walcy Borges- SESM | S26: 23/7/2025 | W26: FALSE | Y26: =VLOOKUP($B26,'Rascunho - PRI'!B25:X627,23,FALSE) -> 0 | Z26: =VLOOKUP($B26,'Rascunho - PRI'!B25:X627,23,FALSE) -> 0
B27: 51475 | D27: O Operador do Sistema Submariono definiu equipe multidisciplinar responsável pela elaboração e revisão de Planos de Resposta a Emergência, considerando no mínimo a qualificação e experiência dos membros, a dimensão do(s) cenário(s) acidentais, a complexidade da atividade, do Sistema Submarino, da operação ou do empreendimento a ser analisado? | E27: RESOLUÇÃO ANP Nº 41, DE 09 DE OUTUBRO DE 2015 | F27: Aprova o Regulamento Técnico do Sistema de Gerenciamento de Segurança Operacional de Sistemas Submarinos - SGSS. | G27: Anexo Item 18.2.1 | H27: SEGURANÇA OPERACIONAL - Sistemas Submarinos | I27: Conforme | J27: Conforme Quadro 3 ¿ Lista de participantes, função e disciplina dos responsáveis técnicos - PE-3BUZ-00100 - PLANO DE RESPOSTA A EMERGÊNCIAS NAS PLATAFORMAS. Sistema: Portal de Gestão / INFOPAE Sandra Nery- LNGH | O27: Gerir Prontidão, Emergência e Contingência | P27: Não Respondida | Q27: Não Respondida | R27: Walcy Borges- SESM | S27: 30/5/2025 | W27: FALSE | Y27: =VLOOKUP($B27,'Rascunho - PRI'!B26:X628,23,FALSE) -> 0 | Z27: =VLOOKUP($B27,'Rascunho - PRI'!B26:X628,23,FALSE) -> 0
B28: 51628 | D28: Foi estabelecido pelo Operador da Instalação sistemas confiáveis e eficazes de comunicação e alarme, bem como procedimentos de comunicação interna e externa, incluindo agências reguladoras e demais autoridades governamentais competentes? | E28: RESOLUÇÃO ANP Nº 43, DE 06 DE DEZEMBRO DE 2007 | F28: Institui o Regime de Segurança Operacional para as Instalações de Perfuração e Produção de Petróleo e Gás Natural. | G28: Prática de Gestão 14 - Item 14.5 | H28: SEGURANÇA OPERACIONAL - Atividade de Operação e Produção Marítima | I28: Conforme | J28: Sim, conforme PE-3BUZ-00100- PLANO DE RESPOSTA A EMERGÊNCIAS NAS PLATAFORMAS. Fabio Mota- DXV9 | O28: Gerir Prontidão, Emergência e Contingência | P28: Não Respondida | Q28: Não Respondida | R28: Walcy Borges- SESM | S28: 30/5/2025 | W28: FALSE | Y28: =VLOOKUP($B28,'Rascunho - PRI'!B27:X629,23,FALSE) -> 0 | Z28: =VLOOKUP($B28,'Rascunho - PRI'!B27:X629,23,FALSE) -> 0
B29: 80587 | D29: As plataformas são dotadas de sistemas fixos de extinção de incêndio eficazes, de acordo com as classes de fogo possíveis e o potencial de incêndio na área a ser protegida? | E29: NR-37 | F29: SEGURANÇA E SAÚDE EM PLATAFORMAS DE PETRÓLEO. | G29: Item 37.25.6.2 | H29: ATIVIDADES OFFSHORE - COMBATE E PREVENÇÃO A INCÊNDIOS (GERAL) | I29: Conforme | J29: Conforme Safety Plan _x000D_ I-DE-3010.0F-5400-947-EG7-020 (P-74)_x000D_ I-DE-3010.0G-5400-947-RG1-001 (P-75)_x000D_ I-DE-3010.0H-5423-940-EA9-701 (P-76)_x000D_ I-DE-3010.0J-5400-947-RG1-001 (P-77)_x000D_ Sistema: SINDOTEC_x000D_ _x000D_ _x000D_ Walcy Borges- SESM | K29: Conforme Safety Plan I-DE-3010.0F-5400-947-EG7-020 (P-74) I-DE-3010.0G-5400-947-RG1-001 (P-75) I-DE-3010.0H-5423-940-EA9-701 (P-76) I-DE-3010.0J-5400-947-RG1-001 (P-77) | L29: Sindotec | M29: Conforme Safety Plan I-DE-3010.0F-5400-947-EG7-020 (P-74) I-DE-3010.0G-5400-947-RG1-001 (P-75) I-DE-3010.0H-5423-940-EA9-701 (P-76) I-DE-3010.0J-5400-947-RG1-001 (P-77) | N29: Sindotec | O29: Gerir Prontidão, Emergência e Contingência | P29: Respondida | Q29: Respondida | R29: Walcy Borges- SESM | S29: 8/5/2025 | T29: 46050 | W29: FALSE | Y29: =VLOOKUP($B29,'Rascunho - PRI'!B28:X630,23,FALSE) -> 0 | Z29: =VLOOKUP($B29,'Rascunho - PRI'!B28:X630,23,FALSE) -> 0
B30: 83725 | D30: A empresa assegura a disponibilidade dos serviços de emergência e salvamento, e de simulados, quando da realização de trabalhos em espaços confinados? | E30: NR-33 | F30: SEGURANÇA E SAÚDE NO TRABALHO EM ESPAÇOS CONFINADO. | G30: Item 33.3.1, h | H30: ESPAÇOS CONFINADOS - Executar ou fiscalizar atividades em espaços confinados | I30: Conforme | J30: Simulados de emergência - PE-2SMS-00074 GERIR TREINAMENTOS DE CONTINGÊNCIA E SIMULADOS NO E&P (Cenário CE4) Manual de Segurança - PE-1PBR-00208 MANUAL DE SEGURANÇA (MS) Permissão de Trabalho - PE-1PBR-00210 MS - PERMISSÃO PARA TRABALHO Sistema: Portal de Gestão Walcy Borges- SESM | K30: Simulados de emergência - PE-2SMS-00074 GERIR TREINAMENTOS DE CONTINGÊNCIA E SIMULADOS NO E&P (Cenário CE4) Manual de Segurança - PE-1PBR-00208 MANUAL DE SEGURANÇA (MS) Permissão de Trabalho - PE-1PBR-00210 MS - PERMISSÃO PARA TRABALHO | L30: Portal de Gestão | M30: Simulados de emergência - PE-2SMS-00074 GERIR TREINAMENTOS DE CONTINGÊNCIA E SIMULADOS NO E&P (Cenário CE4) Manual de Segurança - PE-1PBR-00208 MANUAL DE SEGURANÇA (MS) Permissão de Trabalho - PE-1PBR-00210 MS - PERMISSÃO PARA TRABALHO | N30: Portal de Gestão | O30: Gerir Prontidão, Emergência e Contingência | P30: Respondida | Q30: Respondida | R30: Walcy Borges- SESM | S30: 8/5/2025 | T30: 46050 | W30: FALSE | Y30: =VLOOKUP($B30,'Rascunho - PRI'!B29:X631,23,FALSE) -> 0 | Z30: =VLOOKUP($B30,'Rascunho - PRI'!B29:X631,23,FALSE) -> 0
B31: 51443 | D31: Os critérios para a formação da equipe de investigadores consideram a complexidade e o potencial de dano do Incidente; a inclusão de pelo menos um membro da equipe com amplo conhecimento da técnica de investigação a ser utilizada; a necessidade de inclusão de um membro da equipe com conhecimento da tarefa ou ambiente de trabalho relacionado ao Incidente; a necessidade de especialista técnico; e caso o Incidente envolva uma empresa contratada, a necessidade da inclusão de um empregado dessa empresa? | E31: RESOLUÇÃO ANP Nº 41, DE 09 DE OUTUBRO DE 2015 | F31: Aprova o Regulamento Técnico do Sistema de Gerenciamento de Segurança Operacional de Sistemas Submarinos - SGSS. | G31: Anexo Item 14.3.2 | H31: SEGURANÇA OPERACIONAL - Sistemas Submarinos | I31: Conforme | J31: "PP-1PBR-00150 - GERIR ANOMALIAS DE SMS._x000D_ _x000D_ Sistema: SAP-SMS"_x000D_ Sandra Nery- LNGH | O31: Gerir Prontidão, Emergência e Contingência | P31: Não Respondida | Q31: Não Respondida | R31: Walcy Borges- SESM | S31: 30/5/2025 | W31: FALSE | Y31: =VLOOKUP($B31,'Rascunho - PRI'!B30:X632,23,FALSE) -> 0 | Z31: =VLOOKUP($B31,'Rascunho - PRI'!B30:X632,23,FALSE) -> 0
B32: 51480 | D32: São emitidos relatórios de avaliação de desempenho do simulado? | E32: RESOLUÇÃO ANP Nº 41, DE 09 DE OUTUBRO DE 2015 | F32: Aprova o Regulamento Técnico do Sistema de Gerenciamento de Segurança Operacional de Sistemas Submarinos - SGSS. | G32: Anexo Item 18.5.2 | H32: SEGURANÇA OPERACIONAL - Sistemas Submarinos | I32: Conforme | J32: PE-2SMS-00074 GERIR TREINAMENTOS DE CONTINGÊNCIA E SIMULADOS NO E&P_x000D_ _x000D_ UN-BUZ SMS SEG - Documentos\2 - Interna\04 - Contingência, Prontidão e Resposta\01. Simulados\01 - Simulado N1_x000D_ _x000D_ Sistema: Portal de Gestão / BDoc_x000D_ Sandra Nery- LNGH | O32: Gerir Prontidão, Emergência e Contingência | P32: Não Respondida | Q32: Não Respondida | R32: Walcy Borges- SESM | S32: 30/5/2025 | W32: FALSE | Y32: =VLOOKUP($B32,'Rascunho - PRI'!B31:X633,23,FALSE) -> 0 | Z32: =VLOOKUP($B32,'Rascunho - PRI'!B31:X633,23,FALSE) -> 0
B33: 51667 | D33: O Plano de Resposta à Emergência para controle de poço está integrado aos demais planos de emergência? | E33: RESOLUÇÃO ANP Nº 46, DE 01 DE NOVEMBRO DE 2016 | F33: Aprova o Regime de Segurança Operacional para Integridade de Poços de Petróleo e Gás Natural, que estabelece os requisitos de segurança operacional e de preservação do meio ambiente para perfuração, completação, avaliação, intervenção, produção e abandono de poços de petróleo e gás natural. | G33: Item 14.1, 14.2 e 14.3 | H33: SEGURANÇA OPERACIONAL - Integridade de Poços | I33: Conforme | J33: " PE-2POC-00811- PRE POÇOS - PLANO DE RESPOSTA A EMERGÊNCIAS_x000D_ _x000D_ PE-3UBS-00627 PEVO-BS - PLANO DE EMERGÊNCIA PARA VAZAMENTO DE ÓLEO NA ÁREA GEOGRÁFICA DA BACIA DE SANTOS (AGBS)_x000D_ _x000D_ Sistema: Portal de Gestão / INFOPAE"_x000D_ Sandra Nery- LNGH | O33: Gerir Prontidão, Emergência e Contingência | P33: Não Respondida | Q33: Não Respondida | R33: Walcy Borges- SESM | S33: 30/5/2025 | W33: FALSE | Y33: =VLOOKUP($B33,'Rascunho - PRI'!B32:X634,23,FALSE) -> 0 | Z33: =VLOOKUP($B33,'Rascunho - PRI'!B32:X634,23,FALSE) -> 0
B34: 80391 | D34: A operadora da instalação disponibiliza meios de resgate de emergência durante todo o período de pouso e decolagem de aeronaves na plataforma, conforme prescrito na NORMAM/DPC? | E34: NR-37 | F34: SEGURANÇA E SAÚDE EM PLATAFORMAS DE PETRÓLEO. | G34: Item 37.28.3 | H34: ATIVIDADES OFFSHORE - RESPOSTA A EMERGÊNCIA | I34: Conforme | J34: Conforme procedimento PE-3BUZ-00100 PLANO DE RESPOSTA A EMERGÊNCIAS NAS PLATAFORMAS Anexo A Sistema: Portal de Gestão / INFOPAE Walcy Borges- SESM | K34: Conforme procedimento PE-3BUZ-00100 PLANO DE RESPOSTA A EMERGÊNCIAS NAS PLATAFORMAS | L34: Portal de Gestão / INFOPAE | M34: Conforme procedimento PE-3BUZ-00100 PLANO DE RESPOSTA A EMERGÊNCIAS NAS PLATAFORMAS | N34: Portal de Gestão / INFOPAE | O34: Gerir Prontidão, Emergência e Contingência | P34: Respondida | Q34: Respondida | R34: Walcy Borges- SESM | S34: 8/5/2025 | T34: 46050 | U34: Anexo A | W34: FALSE | Y34: =VLOOKUP($B34,'Rascunho - PRI'!B33:X635,23,FALSE) -> 0 | Z34: =VLOOKUP($B34,'Rascunho - PRI'!B33:X635,23,FALSE) -> 0
B35: 80429 | D35: Ao término do seu turno, o operador do equipamento deve consigna, em livro próprio ou em meio eletrônico, as anormalidades observadas em relação ao seu funcionamento? | E35: NR-37 | F35: SEGURANÇA E SAÚDE EM PLATAFORMAS DE PETRÓLEO. | G35: Item 37.20.3.7 | H35: ATIVIDADES OFFSHORE - MOVIMENTAÇÃO DE CARGAS | I35: Conforme | J35: o operador do equipamento consigna, em livro próprio ou em meio eletrônico, as anormalidades observadas em relação ao seu funcionamento conforme anexo e Conforme PE-1PBR-00223. | O35: Gerir Prontidão, Emergência e Contingência | P35: Não Respondida | Q35: Não Respondida | R35: Walcy Borges- SESM | S35: 28/2/2025 | W35: FALSE | Y35: =VLOOKUP($B35,'Rascunho - PRI'!B34:X636,23,FALSE) -> 0 | Z35: =VLOOKUP($B35,'Rascunho - PRI'!B34:X636,23,FALSE) -> 0
B36: 51425 | D36: A organização tem conhecimento de que, visando à consolidação de uma cultura de segurança operacional e ao comprometimento com a melhoria contínua do sistema de gerenciamento da segurança operacional, deve-se executar os requisitos descritos nos subitens 6.1? | E36: RESOLUÇÃO ANP Nº 41, DE 09 DE OUTUBRO DE 2015 | F36: Aprova o Regulamento Técnico do Sistema de Gerenciamento de Segurança Operacional de Sistemas Submarinos - SGSS. | G36: Anexo Item 6.1 | H36: SEGURANÇA OPERACIONAL - Sistemas Submarinos | I36: Conforme | J36: PL-0SPB-00002 - POLÍTICA DE SEGURANÇA, MEIO AMBIENTE E SAÚDE - SMS _x000D_ _x000D_ PE-2E&P-01241 INTERAÇÃO EM SEGURANÇA "INTERAGE" NO E&P_x000D_ _x000D_ PP-3BUZ-00001 PROGRAMA DE GERENCIAMENTO DA INTEGRIDADE DOS SISTEMAS SUBMARINOS DE PRODUÇÃO DE BÚZIOS_x000D_ _x000D_ Sistema: Portal de Gestão / Sistema Interage / https://portal.petrobras.com.br/group/portal-petrobras/sobre-nos/nossa-estrategia_x000D_ Sandra Nery- LNGH | O36: Gerir Prontidão, Emergência e Contingência | P36: Não Respondida | Q36: Não Respondida | R36: Walcy Borges- SESM | S36: 30/5/2025 | W36: FALSE | Y36: =VLOOKUP($B36,'Rascunho - PRI'!B35:X637,23,FALSE) -> 0 | Z36: =VLOOKUP($B36,'Rascunho - PRI'!B35:X637,23,FALSE) -> 0
B37: 51447 | D37: O Operador do Sistema Submarino estabelece, implementa e documenta programa de treinamento para os membros da equipe de resposta a emergência para todos os cenários emergenciais? | E37: RESOLUÇÃO ANP Nº 41, DE 09 DE OUTUBRO DE 2015 | F37: Aprova o Regulamento Técnico do Sistema de Gerenciamento de Segurança Operacional de Sistemas Submarinos - SGSS. | G37: Anexo Item 18.3.3 | H37: SEGURANÇA OPERACIONAL - Sistemas Submarinos | I37: Conforme | J37: PP-1PBR-00474 MANTER ESTADO DE PRONTIDÃO_x000D_ _x000D_ Sistema: Portal de Gestão. Sandra Nery- LNGH | O37: Gerir Prontidão, Emergência e Contingência | P37: Não Respondida | Q37: Não Respondida | R37: Walcy Borges- SESM | S37: 30/5/2025 | W37: FALSE | Y37: =VLOOKUP($B37,'Rascunho - PRI'!B36:X638,23,FALSE) -> 0 | Z37: =VLOOKUP($B37,'Rascunho - PRI'!B36:X638,23,FALSE) -> 0
